<?xml version="1.0"?>
<sdf version="1.9">
  <model name="aiapaec">
    <pose degrees="true">0 0 0 0 0 0</pose>

    <!-- base_link -->


    <link name="base_link">
      <inertial>
        <pose>0.0 0.0 0.0 0 0 0</pose>    
        <mass>53.972</mass>
        <inertia>
          <ixx>1.1866349780349186</ixx>
          <ixy>0</ixy>
          <ixz>0</ixz>
          <iyy>8.449738344749418</iyy>
          <iyz>0</iyz>
          <izz>8.449738344749418</izz>
        </inertia>
      </inertial>
      <visual name="base_link_visual">
        <pose degrees="true">0 0 0 0 0 0</pose>
        <geometry>
          <mesh>
            <uri>model://aiapaec/meshes/base_link.stl</uri>
            <scale>1 1 1</scale>
          </mesh>
        </geometry>
        <material>
          <ambient>0.9098 0.67843 0.13725 1</ambient>
          <diffuse>0.9098 0.67843 0.13725 1</diffuse>
          <specular>0.1 0.1 0.1 1</specular>
          <emissive>0 0 0 0</emissive>
        </material>
      </visual> 

      <collision name="base_link_collision">
        <pose>0.0 0.0 1 0 0 0</pose>
        <geometry>
          <box>
            <size>1.310 0.20 0.20</size>
          </box> 
        </geometry>
      </collision>

      <sensor
            element_id="base_link" action="add"
            name="aiapaec_dvl"
            type="custom" gz:type="dvl">
          <!-- Account for DVL mounting position and base link rotation -->
          <pose degrees="true">0 0 0 0 0 0</pose>
          <always_on>1</always_on>
          <update_rate>30</update_rate>
          <topic>/aiapaec/gazebo/dvl</topic>
          <gz:dvl>
            <type>phased_array</type>
            <arrangement degrees="true">
              <beam id="1">
                <aperture>2.1</aperture>
                <rotation>45</rotation>
                <tilt>5</tilt>
              </beam>
              <beam>
                <aperture>2.1</aperture>
                <rotation>120</rotation>
                <tilt>5</tilt>
              </beam>
              <beam>
                <aperture>2.1</aperture>
                <rotation>-45</rotation>
                <tilt>5</tilt>
              </beam>
              <beam>
                <aperture>2.1</aperture>
                <rotation>-120</rotation>
                <tilt>5</tilt>
              </beam>
            </arrangement>
            <!---->
            <tracking>
              <bottom_mode>
                <when>best</when>
                <visualize>true</visualize>
              </bottom_mode>
            </tracking> 
            <!-- Roughly 1 m resolution at a 100m -->
            <resolution>0.01</resolution>
            <!-- Approximate maximum range @ ~14.4v -->
            <maximum_range>100.</maximum_range>
            <minimum_range>0.1</minimum_range>
            <!-- ENU to SFM -->
            <reference_frame>0 0 0 0 0 0</reference_frame>
          </gz:dvl>
        </sensor>
        <!--
            See https://www.spartonnavex.com/product/ahrs-m2 
        -->
        <sensor
            element_id="base_link"
            action="add"
            name="aiapaec_imu"
            type="imu">
        <!--IMU in a Sparton AHRS-M2 -->
          <always_on>1</always_on>
          <pose degrees="true">0 0 0 0 0 0</pose>
          <imu>
            <orientation_reference_frame>base_link</orientation_reference_frame>
            <enable_orientation>1</enable_orientation>
          </imu>
          <update_rate>30</update_rate>
          <topic>/aiapaec/gazebo/imu</topic>
        </sensor>   

    </link>

    <plugin
        filename="gz-sim-odometry-publisher-system"
        name="gz::sim::systems::OdometryPublisher">
        <odom_frame>base_link</odom_frame>
        <odom_publish_frequency>400</odom_publish_frequency> 
        <dimensions>3</dimensions>
        <rpy_offset>0 0 0</rpy_offset>
    </plugin>

    <plugin
      filename="gz-sim-buoyancy-engine-system"
      name="gz::sim::systems::BuoyancyEngine">
      <link_name>base_link</link_name>
      <namespace>aiapaec</namespace>
      <min_volume>0.04000</min_volume>
      <neutral_volume>0.05267</neutral_volume>
      <default_volume>0.05267</default_volume>
      <max_volume>0.0600</max_volume>
      <max_inflation_rate>0.00001</max_inflation_rate>
      <fluid_density>1030</fluid_density>
      <surface>0</surface>
    </plugin>

<!-- Hydrodynamics plugin -->
    <plugin
      filename="gz-sim-hydrodynamics-system"
      name="gz::sim::systems::Hydrodynamics">
      <link_name>base_link</link_name>
      <water_density>1030.0</water_density>
      <!-- Added mass: -->
        <xDotU>7.830329E-01</xDotU>  <!-- -7.830329E-01 (Referencial calculus) -->
        <yDotV>-5.062522E+01</yDotV>  
        <zDotW>-5.062522E+01</zDotW>  
        <kDotP>-3.913712E-01</kDotP>  
        <mDotQ>-6.885066E+00</mDotQ>  
        <nDotR>-6.885066E+00</nDotR>  
        <!-- First order stability derivative: -->
        <xU>0.0</xU>
        <yV>0.0</yV>
        <zW>0.0</zW>
        <kP>0.0</kP>
        <mQ>0.0</mQ>
        <nR>0.0</nR>
        <!-- Second order stability derivative: -->
        <xUabsU>-1.479637E+00</xUabsU> <!-- -1.479637E+00 -->
        <yVabsV>-1.258586E+02</yVabsV> 
        <zWabsW>-1.258586E+02</zWabsW> 
        <kPabsP>0.000000E+00</kPabsP>  
        <mQabsQ>-6.347858E+00</mQabsQ> 
        <nRabsR>-6.347858E+00</nRabsR> 
    </plugin>

<!-- Motor_derecho (Thruster 1)-->

    <link name="thruster1">
      <pose>-0.49387 -0.12499 0.00010437 -1.5708 0 0</pose> <!---0.49387 -0.12499 0.00010437 -1.5708 0 0 Pose to inertias-->
      <visual name="thruster1_visual">
        <pose>0 0 0 0 0 0</pose> <!--Pose to meshes-->
        <geometry>
          <mesh>
            <uri>model://aiapaec/meshes/thruster1.stl</uri>
            <scale>1 1 1</scale>
          </mesh>
        </geometry>
        <material>
          <ambient>0.79216 0.81961 0.93333 1</ambient>
          <diffuse>0.79216 0.81961 0.93333 1</diffuse>
          <specular>0.1 0.1 0.1 1</specular>
          <emissive>0 0 0 0</emissive>
        </material>
      </visual>
       <inertial>
        <mass>0.0927</mass>
        <inertia>
          <ixx>0.0001</ixx>
          <ixy>0</ixy>
          <ixz>0</ixz>
          <iyy>0.0001</iyy>
          <iyz>0</iyz>
          <izz>0.0001</izz>
        </inertia>
      </inertial>
      <collision name="thruster1_collision">
        <geometry>
          <box>
            <size>0.03 0.1 0.03</size>
          </box>
        </geometry>
      </collision>
    </link>

<!-- Motor_izquierda (Thruster 2)-->

    <link name="thruster2">
      <pose>-0.49387 0.12499 -0.00010437 1.5708 0 0</pose> 
      <visual name="thruster2_visual">
        <pose>0 0 0 0 0 0</pose>
        <geometry>
          <mesh>
            <uri>model://aiapaec/meshes/thruster2.stl</uri>
            <scale>1 1 1</scale>
          </mesh>
        </geometry>
        <material>
          <ambient>0.79216 0.81961 0.93333 1</ambient>
          <diffuse>0.79216 0.81961 0.93333 1</diffuse>
          <specular>0.1 0.1 0.1 1</specular>
          <emissive>0 0 0 0</emissive>
        </material>
      </visual>
      <inertial>
        <mass>0.0927</mass>
        <inertia>
          <ixx>0.0001</ixx>
          <ixy>0</ixy>
          <ixz>0</ixz>
          <iyy>0.0001</iyy>
          <iyz>0</iyz>
          <izz>0.0001</izz>
        </inertia>
      </inertial>
      <collision name="thruster2_collision">
        <geometry>
          <box>
            <size>0.03 0.1 0.03</size>
          </box>
        </geometry>
      </collision>
    </link>
    
<!-- Motor_medio_link (Thruster 3)--> 

    <link name="thruster3">
      <pose>0.24 0.001871 0 1.5708 0 1.5708</pose> <!--0.24 0.001871 0 1.5708 0 1.5708--> 
      <visual name="thruster3_visual">
        <pose>0.0085526 4.0292E-08 -1.9993E-08 0 0 0</pose> <!--0.0085526 4.0292E-08 -1.9993E-08 0 0 0-->
        <geometry>
          <mesh>
            <uri>model://aiapaec/meshes/thruster3.stl</uri>
            <scale>1 1 1</scale>
          </mesh>
        </geometry>
        <material>
          <ambient>0.79216 0.81961 0.93333 1</ambient>
          <diffuse>0.79216 0.81961 0.93333 1</diffuse>
          <specular>0.1 0.1 0.1 1</specular>
          <emissive>0 0 0 0</emissive>
        </material>
      </visual>
       <inertial>
        <mass>0.0927</mass>
        <inertia>
          <ixx>0.0001</ixx>
          <ixy>0</ixy>
          <ixz>0</ixz>
          <iyy>0.0001</iyy>
          <iyz>0</iyz>
          <izz>0.0001</izz>
        </inertia>
      </inertial>
      <collision name="thruster3_collision">
        <geometry>
          <box>
            <size>0.03 0.1 0.03</size>
          </box>
        </geometry>
      </collision>
    </link>

<!-- Joint base_link/thruster1-->   

    <joint name="thruster1_joint" type="revolute">
      <pose>0 0 0 0 0 0</pose>
      <parent>base_link</parent>
      <child>thruster1</child>
      <axis>
        <xyz>1 0 0</xyz>
      </axis>
    </joint>

<!-- Joint base_link/thruster2-->   

    <joint name="thruster2_joint" type="revolute">
      <pose>0 0 0 0 0 0</pose>
      <parent>base_link</parent>
      <child>thruster2</child>
      <axis>
        <xyz>1 0 0</xyz>
      </axis>
    </joint>      

<!-- Joint base_link/thruster3-->   

    <joint name="thruster3_joint" type="revolute">
      <pose>0 0 0 0 0 0</pose>
      <parent>base_link</parent>
      <child>thruster3</child>
      <axis>
        <xyz>1 0 0</xyz>
      </axis>
    </joint>      
   
<!-- Plugin thruster-->

<!-- thruster 1-->

    <plugin
        filename="gz-sim-thruster-system"
        name="gz::sim::systems::Thruster">
      <namespace>aiapaec</namespace>
      <joint_name>thruster1_joint</joint_name>
      <thrust_coefficient>0.02</thrust_coefficient>
      <fluid_density>1030.0</fluid_density>
      <propeller_diameter>0.1</propeller_diameter>
      <velocity_control>true</velocity_control>
      <use_angvel_cmd>false</use_angvel_cmd>
    </plugin>   

<!-- thruster 2-->

    <plugin
        filename="gz-sim-thruster-system"
        name="gz::sim::systems::Thruster">
      <namespace>aiapaec</namespace>
      <joint_name>thruster2_joint</joint_name>
      <thrust_coefficient>0.02</thrust_coefficient>
      <fluid_density>1030.0</fluid_density>
      <propeller_diameter>0.1</propeller_diameter>
      <velocity_control>true</velocity_control>
      <use_angvel_cmd>false</use_angvel_cmd>
    </plugin> 

<!-- thruster 3-->

    <plugin
        filename="gz-sim-thruster-system"
        name="gz::sim::systems::Thruster">
      <namespace>aiapaec</namespace>
      <joint_name>thruster3_joint</joint_name>
      <thrust_coefficient>0.02</thrust_coefficient>
      <fluid_density>1030.0</fluid_density>
      <propeller_diameter>0.1</propeller_diameter>
      <velocity_control>true</velocity_control>
      <use_angvel_cmd>false</use_angvel_cmd>
    </plugin>
    
  </model>
</sdf>